Workbook

Sheet Summary
A1: Signal & Noise 2026
A2: How social media talked about LLMs, Jan–Sep 2026 · hand-coded sample of 387 posts · Northbank Media Lab
A4: Share of the conversation: each theme's % of that month's LLM posts
A5: Month | B5: Agentic coding | C5: Open-weight models | D5: Reasoning & test-time compute | E5: Prices & tokens | F5: On-device AI | G5: Regulation & policy | H5: Benchmarks & evals | I5: Compute & energy | J5: Multimodal & voice | K5: Safety & trust
A6: Jan | B6: =Counts!B6/Counts!$L6 -> 0.090909091 | C6: =Counts!C6/Counts!$L6 -> 0.12121212 | D6: =Counts!D6/Counts!$L6 -> 0.18181818 | E6: =Counts!E6/Counts!$L6 -> 0.12121212 | F6: =Counts!F6/Counts!$L6 -> 0.060606061 | G6: =Counts!G6/Counts!$L6 -> 0.060606061 | H6: =Counts!H6/Counts!$L6 -> 0.12121212 | I6: =Counts!I6/Counts!$L6 -> 0.090909091 | ... K6: =Counts!K6/Counts!$L6 -> 0.060606061
A7: Feb | B7: =Counts!B7/Counts!$L7 -> 0.11111111 | C7: =Counts!C7/Counts!$L7 -> 0.11111111 | D7: =Counts!D7/Counts!$L7 -> 0.16666667 | E7: =Counts!E7/Counts!$L7 -> 0.11111111 | F7: =Counts!F7/Counts!$L7 -> 0.055555556 | G7: =Counts!G7/Counts!$L7 -> 0.055555556 | H7: =Counts!H7/Counts!$L7 -> 0.11111111 | I7: =Counts!I7/Counts!$L7 -> 0.11111111 | ... K7: =Counts!K7/Counts!$L7 -> 0.055555556
A8: Mar | B8: =Counts!B8/Counts!$L8 -> 0.10526316 | C8: =Counts!C8/Counts!$L8 -> 0.13157895 | D8: =Counts!D8/Counts!$L8 -> 0.13157895 | E8: =Counts!E8/Counts!$L8 -> 0.10526316 | F8: =Counts!F8/Counts!$L8 -> 0.052631579 | G8: =Counts!G8/Counts!$L8 -> 0.078947368 | H8: =Counts!H8/Counts!$L8 -> 0.10526316 | I8: =Counts!I8/Counts!$L8 -> 0.10526316 | ... K8: =Counts!K8/Counts!$L8 -> 0.078947368
A9: Apr | B9: =Counts!B9/Counts!$L9 -> 0.15 | C9: =Counts!C9/Counts!$L9 -> 0.15 | D9: =Counts!D9/Counts!$L9 -> 0.1 | E9: =Counts!E9/Counts!$L9 -> 0.1 | F9: =Counts!F9/Counts!$L9 -> 0.05 | G9: =Counts!G9/Counts!$L9 -> 0.075 | H9: =Counts!H9/Counts!$L9 -> 0.1 | I9: =Counts!I9/Counts!$L9 -> 0.1 | ... K9: =Counts!K9/Counts!$L9 -> 0.075
A10: May | B10: =Counts!B10/Counts!$L10 -> 0.13636364 | C10: =Counts!C10/Counts!$L10 -> 0.13636364 | D10: =Counts!D10/Counts!$L10 -> 0.090909091 | E10: =Counts!E10/Counts!$L10 -> 0.090909091 | F10: =Counts!F10/Counts!$L10 -> 0.068181818 | G10: =Counts!G10/Counts!$L10 -> 0.090909091 | H10: =Counts!H10/Counts!$L10 -> 0.090909091 | I10: =Counts!I10/Counts!$L10 -> 0.090909091 | ... K10: =Counts!K10/Counts!$L10 -> 0.090909091
A11: Jun | B11: =Counts!B11/Counts!$L11 -> 0.17391304 | C11: =Counts!C11/Counts!$L11 -> 0.10869565 | D11: =Counts!D11/Counts!$L11 -> 0.086956522 | E11: =Counts!E11/Counts!$L11 -> 0.086956522 | F11: =Counts!F11/Counts!$L11 -> 0.086956522 | G11: =Counts!G11/Counts!$L11 -> 0.086956522 | H11: =Counts!H11/Counts!$L11 -> 0.065217391 | I11: =Counts!I11/Counts!$L11 -> 0.10869565 | ... K11: =Counts!K11/Counts!$L11 -> 0.086956522
A12: Jul | B12: =Counts!B12/Counts!$L12 -> 0.16 | C12: =Counts!C12/Counts!$L12 -> 0.12 | D12: =Counts!D12/Counts!$L12 -> 0.08 | E12: =Counts!E12/Counts!$L12 -> 0.08 | F12: =Counts!F12/Counts!$L12 -> 0.08 | G12: =Counts!G12/Counts!$L12 -> 0.12 | H12: =Counts!H12/Counts!$L12 -> 0.06 | I12: =Counts!I12/Counts!$L12 -> 0.1 | ... K12: =Counts!K12/Counts!$L12 -> 0.08
A13: Aug | B13: =Counts!B13/Counts!$L13 -> 0.18 | C13: =Counts!C13/Counts!$L13 -> 0.12 | D13: =Counts!D13/Counts!$L13 -> 0.08 | E13: =Counts!E13/Counts!$L13 -> 0.08 | F13: =Counts!F13/Counts!$L13 -> 0.08 | G13: =Counts!G13/Counts!$L13 -> 0.08 | H13: =Counts!H13/Counts!$L13 -> 0.06 | I13: =Counts!I13/Counts!$L13 -> 0.12 | ... K13: =Counts!K13/Counts!$L13 -> 0.08
A14: Sep | B14: =Counts!B14/Counts!$L14 -> 0.2 | C14: =Counts!C14/Counts!$L14 -> 0.12 | D14: =Counts!D14/Counts!$L14 -> 0.06 | E14: =Counts!E14/Counts!$L14 -> 0.08 | F14: =Counts!F14/Counts!$L14 -> 0.08 | G14: =Counts!G14/Counts!$L14 -> 0.08 | H14: =Counts!H14/Counts!$L14 -> 0.06 | I14: =Counts!I14/Counts!$L14 -> 0.12 | ... K14: =Counts!K14/Counts!$L14 -> 0.08
A15: Jan–Sep | B15: =Counts!B15/Counts!$L15 -> 0.1498708 | C15: =Counts!C15/Counts!$L15 -> 0.12403101 | D15: =Counts!D15/Counts!$L15 -> 0.10335917 | E15: =Counts!E15/Counts!$L15 -> 0.093023256 | F15: =Counts!F15/Counts!$L15 -> 0.069767442 | G15: =Counts!G15/Counts!$L15 -> 0.082687339 | H15: =Counts!H15/Counts!$L15 -> 0.082687339 | I15: =Counts!I15/Counts!$L15 -> 0.10594315 | ... K15: =Counts!K15/Counts!$L15 -> 0.07751938
A18: Change and tone by theme
A19: Theme | B19: Share of all posts | C19: Share in Jan | D19: Share in Sep | E19: Change | F19: positive | G19: neutral | H19: negative
A20: Agentic coding | B20: =COUNTIF(Posts!$F$2:$F$388,$A20)/COUNTA(Posts!$F$2:$F$388) -> 0.1498708 | C20: {=INDEX($B$6:$K$6,MATCH($A20,$B$5:$K$5,0))} -> 0.090909091 | D20: {=INDEX($B$14:$K$14,MATCH($A20,$B$5:$K$5,0))} -> 0.2 | E20: =ROUND((D20-C20)*100,0) -> 11 | F20: =COUNTIFS(Posts!$F$2:$F$388,$A20,Posts!$G$2:$G$388,F$19)/COUNTIF(Posts!$F$2:$F$388,$A20) -> 0.48275862 | G20: =COUNTIFS(Posts!$F$2:$F$388,$A20,Posts!$G$2:$G$388,G$19)/COUNTIF(Posts!$F$2:$F$388,$A20) -> 0.4137931 | H20: =COUNTIFS(Posts!$F$2:$F$388,$A20,Posts!$G$2:$G$388,H$19)/COUNTIF(Posts!$F$2:$F$388,$A20) -> 0.10344828
A21: Open-weight models | B21: =COUNTIF(Posts!$F$2:$F$388,$A21)/COUNTA(Posts!$F$2:$F$388) -> 0.12403101 | C21: {=INDEX($B$6:$K$6,MATCH($A21,$B$5:$K$5,0))} -> 0.12121212 | D21: {=INDEX($B$14:$K$14,MATCH($A21,$B$5:$K$5,0))} -> 0.12 | E21: =ROUND((D21-C21)*100,0) -> 0 | F21: =COUNTIFS(Posts!$F$2:$F$388,$A21,Posts!$G$2:$G$388,F$19)/COUNTIF(Posts!$F$2:$F$388,$A21) -> 0.47916667 | G21: =COUNTIFS(Posts!$F$2:$F$388,$A21,Posts!$G$2:$G$388,G$19)/COUNTIF(Posts!$F$2:$F$388,$A21) -> 0.3125 | H21: =COUNTIFS(Posts!$F$2:$F$388,$A21,Posts!$G$2:$G$388,H$19)/COUNTIF(Posts!$F$2:$F$388,$A21) -> 0.20833333
A22: Reasoning & test-time compute | B22: =COUNTIF(Posts!$F$2:$F$388,$A22)/COUNTA(Posts!$F$2:$F$388) -> 0.10335917 | C22: {=INDEX($B$6:$K$6,MATCH($A22,$B$5:$K$5,0))} -> 0.18181818 | D22: {=INDEX($B$14:$K$14,MATCH($A22,$B$5:$K$5,0))} -> 0.06 | E22: =ROUND((D22-C22)*100,0) -> -12 | F22: =COUNTIFS(Posts!$F$2:$F$388,$A22,Posts!$G$2:$G$388,F$19)/COUNTIF(Posts!$F$2:$F$388,$A22) -> 0.35 | G22: =COUNTIFS(Posts!$F$2:$F$388,$A22,Posts!$G$2:$G$388,G$19)/COUNTIF(Posts!$F$2:$F$388,$A22) -> 0.525 | H22: =COUNTIFS(Posts!$F$2:$F$388,$A22,Posts!$G$2:$G$388,H$19)/COUNTIF(Posts!$F$2:$F$388,$A22) -> 0.125
A23: Prices & tokens | B23: =COUNTIF(Posts!$F$2:$F$388,$A23)/COUNTA(Posts!$F$2:$F$388) -> 0.093023256 | C23: {=INDEX($B$6:$K$6,MATCH($A23,$B$5:$K$5,0))} -> 0.12121212 | D23: {=INDEX($B$14:$K$14,MATCH($A23,$B$5:$K$5,0))} -> 0.08 | E23: =ROUND((D23-C23)*100,0) -> -4 | F23: =COUNTIFS(Posts!$F$2:$F$388,$A23,Posts!$G$2:$G$388,F$19)/COUNTIF(Posts!$F$2:$F$388,$A23) -> 0.30555556 | G23: =COUNTIFS(Posts!$F$2:$F$388,$A23,Posts!$G$2:$G$388,G$19)/COUNTIF(Posts!$F$2:$F$388,$A23) -> 0.16666667 | H23: =COUNTIFS(Posts!$F$2:$F$388,$A23,Posts!$G$2:$G$388,H$19)/COUNTIF(Posts!$F$2:$F$388,$A23) -> 0.52777778
A24: On-device AI | B24: =COUNTIF(Posts!$F$2:$F$388,$A24)/COUNTA(Posts!$F$2:$F$388) -> 0.069767442 | C24: {=INDEX($B$6:$K$6,MATCH($A24,$B$5:$K$5,0))} -> 0.060606061 | D24: {=INDEX($B$14:$K$14,MATCH($A24,$B$5:$K$5,0))} -> 0.08 | E24: =ROUND((D24-C24)*100,0) -> 2 | F24: =COUNTIFS(Posts!$F$2:$F$388,$A24,Posts!$G$2:$G$388,F$19)/COUNTIF(Posts!$F$2:$F$388,$A24) -> 0.44444444 | G24: =COUNTIFS(Posts!$F$2:$F$388,$A24,Posts!$G$2:$G$388,G$19)/COUNTIF(Posts!$F$2:$F$388,$A24) -> 0.33333333 | H24: =COUNTIFS(Posts!$F$2:$F$388,$A24,Posts!$G$2:$G$388,H$19)/COUNTIF(Posts!$F$2:$F$388,$A24) -> 0.22222222
A25: Regulation & policy | B25: =COUNTIF(Posts!$F$2:$F$388,$A25)/COUNTA(Posts!$F$2:$F$388) -> 0.082687339 | C25: {=INDEX($B$6:$K$6,MATCH($A25,$B$5:$K$5,0))} -> 0.060606061 | D25: {=INDEX($B$14:$K$14,MATCH($A25,$B$5:$K$5,0))} -> 0.08 | E25: =ROUND((D25-C25)*100,0) -> 2 | F25: =COUNTIFS(Posts!$F$2:$F$388,$A25,Posts!$G$2:$G$388,F$19)/COUNTIF(Posts!$F$2:$F$388,$A25) -> 0.53125 | G25: =COUNTIFS(Posts!$F$2:$F$388,$A25,Posts!$G$2:$G$388,G$19)/COUNTIF(Posts!$F$2:$F$388,$A25) -> 0.34375 | H25: =COUNTIFS(Posts!$F$2:$F$388,$A25,Posts!$G$2:$G$388,H$19)/COUNTIF(Posts!$F$2:$F$388,$A25) -> 0.125
A26: Benchmarks & evals | B26: =COUNTIF(Posts!$F$2:$F$388,$A26)/COUNTA(Posts!$F$2:$F$388) -> 0.082687339 | C26: {=INDEX($B$6:$K$6,MATCH($A26,$B$5:$K$5,0))} -> 0.12121212 | D26: {=INDEX($B$14:$K$14,MATCH($A26,$B$5:$K$5,0))} -> 0.06 | E26: =ROUND((D26-C26)*100,0) -> -6 | F26: =COUNTIFS(Posts!$F$2:$F$388,$A26,Posts!$G$2:$G$388,F$19)/COUNTIF(Posts!$F$2:$F$388,$A26) -> 0.5 | G26: =COUNTIFS(Posts!$F$2:$F$388,$A26,Posts!$G$2:$G$388,G$19)/COUNTIF(Posts!$F$2:$F$388,$A26) -> 0.46875 | H26: =COUNTIFS(Posts!$F$2:$F$388,$A26,Posts!$G$2:$G$388,H$19)/COUNTIF(Posts!$F$2:$F$388,$A26) -> 0.03125
A27: Compute & energy | B27: =COUNTIF(Posts!$F$2:$F$388,$A27)/COUNTA(Posts!$F$2:$F$388) -> 0.10594315 | C27: {=INDEX($B$6:$K$6,MATCH($A27,$B$5:$K$5,0))} -> 0.090909091 | D27: {=INDEX($B$14:$K$14,MATCH($A27,$B$5:$K$5,0))} -> 0.12 | E27: =ROUND((D27-C27)*100,0) -> 3 | F27: =COUNTIFS(Posts!$F$2:$F$388,$A27,Posts!$G$2:$G$388,F$19)/COUNTIF(Posts!$F$2:$F$388,$A27) -> 0.2195122 | G27: =COUNTIFS(Posts!$F$2:$F$388,$A27,Posts!$G$2:$G$388,G$19)/COUNTIF(Posts!$F$2:$F$388,$A27) -> 0.36585366 | H27: =COUNTIFS(Posts!$F$2:$F$388,$A27,Posts!$G$2:$G$388,H$19)/COUNTIF(Posts!$F$2:$F$388,$A27) -> 0.41463415
A28: Multimodal & voice | B28: =COUNTIF(Posts!$F$2:$F$388,$A28)/COUNTA(Posts!$F$2:$F$388) -> 0.11111111 | C28: {=INDEX($B$6:$K$6,MATCH($A28,$B$5:$K$5,0))} -> 0.090909091 | D28: {=INDEX($B$14:$K$14,MATCH($A28,$B$5:$K$5,0))} -> 0.12 | E28: =ROUND((D28-C28)*100,0) -> 3 | F28: =COUNTIFS(Posts!$F$2:$F$388,$A28,Posts!$G$2:$G$388,F$19)/COUNTIF(Posts!$F$2:$F$388,$A28) -> 0.37209302 | G28: =COUNTIFS(Posts!$F$2:$F$388,$A28,Posts!$G$2:$G$388,G$19)/COUNTIF(Posts!$F$2:$F$388,$A28) -> 0.44186047 | H28: =COUNTIFS(Posts!$F$2:$F$388,$A28,Posts!$G$2:$G$388,H$19)/COUNTIF(Posts!$F$2:$F$388,$A28) -> 0.18604651
A29: Safety & trust | B29: =COUNTIF(Posts!$F$2:$F$388,$A29)/COUNTA(Posts!$F$2:$F$388) -> 0.07751938 | C29: {=INDEX($B$6:$K$6,MATCH($A29,$B$5:$K$5,0))} -> 0.060606061 | D29: {=INDEX($B$14:$K$14,MATCH($A29,$B$5:$K$5,0))} -> 0.08 | E29: =ROUND((D29-C29)*100,0) -> 2 | F29: =COUNTIFS(Posts!$F$2:$F$388,$A29,Posts!$G$2:$G$388,F$19)/COUNTIF(Posts!$F$2:$F$388,$A29) -> 0.2 | G29: =COUNTIFS(Posts!$F$2:$F$388,$A29,Posts!$G$2:$G$388,G$19)/COUNTIF(Posts!$F$2:$F$388,$A29) -> 0.33333333 | H29: =COUNTIFS(Posts!$F$2:$F$388,$A29,Posts!$G$2:$G$388,H$19)/COUNTIF(Posts!$F$2:$F$388,$A29) -> 0.46666667
A30: All themes | B30: =SUM(B20:B29) -> 1 | C30: =SUM(C20:C29) -> 1 | D30: =SUM(D20:D29) -> 1 | F30: =COUNTIF(Posts!$G$2:$G$388,F$19)/COUNTA(Posts!$G$2:$G$388) -> 0.39276486 | G30: =COUNTIF(Posts!$G$2:$G$388,G$19)/COUNTA(Posts!$G$2:$G$388) -> 0.374677 | H30: =COUNTIF(Posts!$G$2:$G$388,H$19)/COUNTA(Posts!$G$2:$G$388) -> 0.23255814
A32: Illustrative, synthetic data. The 387 fictional posts are a hand-coded sample of a much larger stream. The Counts sheet shows the raw counts.
A35: Chart data: share of the conversation, 4 key themes | G35: Chart data: % of posts that are negative
A36: Month | B36: Agentic coding | C36: Reasoning & test-time compute | D36: Benchmarks & evals | E36: Compute & energy | G36: Theme | H36: % negative
A37: =A6 -> Jan | B37: =B6 -> 0.090909091 | C37: =D6 -> 0.18181818 | D37: =H6 -> 0.12121212 | E37: =I6 -> 0.090909091 | G37: =A26 -> Benchmarks & evals | H37: =H26 -> 0.03125
A38: =A7 -> Feb | B38: =B7 -> 0.11111111 | C38: =D7 -> 0.16666667 | D38: =H7 -> 0.11111111 | E38: =I7 -> 0.11111111 | G38: =A20 -> Agentic coding | H38: =H20 -> 0.10344828
A39: =A8 -> Mar | B39: =B8 -> 0.10526316 | C39: =D8 -> 0.13157895 | D39: =H8 -> 0.10526316 | E39: =I8 -> 0.10526316 | G39: =A22 -> Reasoning & test-time compute | H39: =H22 -> 0.125
A40: =A9 -> Apr | B40: =B9 -> 0.15 | C40: =D9 -> 0.1 | D40: =H9 -> 0.1 | E40: =I9 -> 0.1 | G40: =A25 -> Regulation & policy | H40: =H25 -> 0.125
A41: =A10 -> May | B41: =B10 -> 0.13636364 | C41: =D10 -> 0.090909091 | D41: =H10 -> 0.090909091 | E41: =I10 -> 0.090909091 | G41: =A28 -> Multimodal & voice | H41: =H28 -> 0.18604651
A42: =A11 -> Jun | B42: =B11 -> 0.17391304 | C42: =D11 -> 0.086956522 | D42: =H11 -> 0.065217391 | E42: =I11 -> 0.10869565 | G42: =A21 -> Open-weight models | H42: =H21 -> 0.20833333
A43: =A12 -> Jul | B43: =B12 -> 0.16 | C43: =D12 -> 0.08 | D43: =H12 -> 0.06 | E43: =I12 -> 0.1 | G43: =A24 -> On-device AI | H43: =H24 -> 0.22222222
A44: =A13 -> Aug | B44: =B13 -> 0.18 | C44: =D13 -> 0.08 | D44: =H13 -> 0.06 | E44: =I13 -> 0.12 | G44: Average, all themes | H44: =H30 -> 0.23255814
A45: =A14 -> Sep | B45: =B14 -> 0.2 | C45: =D14 -> 0.06 | D45: =H14 -> 0.06 | E45: =I14 -> 0.12 | G45: =A27 -> Compute & energy | H45: =H27 -> 0.41463415
G46: =A29 -> Safety & trust | H46: =H29 -> 0.46666667
...

Sheet Counts
A1: Post counts by month × theme
A2: COUNTIFS over the Posts sheet · hand-coded sample of 387 posts (synthetic)
A5: Month | B5: Agentic coding | C5: Open-weight models | D5: Reasoning & test-time compute | E5: Prices & tokens | F5: On-device AI | G5: Regulation & policy | H5: Benchmarks & evals | I5: Compute & energy | J5: Multimodal & voice | K5: Safety & trust | L5: All posts
A6: 2026-01 | B6: =COUNTIFS(Posts!$C$2:$C$388,$A6,Posts!$F$2:$F$388,B$5) -> 3 | C6: =COUNTIFS(Posts!$C$2:$C$388,$A6,Posts!$F$2:$F$388,C$5) -> 4 | D6: =COUNTIFS(Posts!$C$2:$C$388,$A6,Posts!$F$2:$F$388,D$5) -> 6 | E6: =COUNTIFS(Posts!$C$2:$C$388,$A6,Posts!$F$2:$F$388,E$5) -> 4 | F6: =COUNTIFS(Posts!$C$2:$C$388,$A6,Posts!$F$2:$F$388,F$5) -> 2 | G6: =COUNTIFS(Posts!$C$2:$C$388,$A6,Posts!$F$2:$F$388,G$5) -> 2 | H6: =COUNTIFS(Posts!$C$2:$C$388,$A6,Posts!$F$2:$F$388,H$5) -> 4 | I6: =COUNTIFS(Posts!$C$2:$C$388,$A6,Posts!$F$2:$F$388,I$5) -> 3 | ... K6: =COUNTIFS(Posts!$C$2:$C$388,$A6,Posts!$F$2:$F$388,K$5) -> 2 | L6: =SUM(B6:K6) -> 33
A7: 2026-02 | B7: =COUNTIFS(Posts!$C$2:$C$388,$A7,Posts!$F$2:$F$388,B$5) -> 4 | C7: =COUNTIFS(Posts!$C$2:$C$388,$A7,Posts!$F$2:$F$388,C$5) -> 4 | D7: =COUNTIFS(Posts!$C$2:$C$388,$A7,Posts!$F$2:$F$388,D$5) -> 6 | E7: =COUNTIFS(Posts!$C$2:$C$388,$A7,Posts!$F$2:$F$388,E$5) -> 4 | F7: =COUNTIFS(Posts!$C$2:$C$388,$A7,Posts!$F$2:$F$388,F$5) -> 2 | G7: =COUNTIFS(Posts!$C$2:$C$388,$A7,Posts!$F$2:$F$388,G$5) -> 2 | H7: =COUNTIFS(Posts!$C$2:$C$388,$A7,Posts!$F$2:$F$388,H$5) -> 4 | I7: =COUNTIFS(Posts!$C$2:$C$388,$A7,Posts!$F$2:$F$388,I$5) -> 4 | ... K7: =COUNTIFS(Posts!$C$2:$C$388,$A7,Posts!$F$2:$F$388,K$5) -> 2 | L7: =SUM(B7:K7) -> 36
A8: 2026-03 | B8: =COUNTIFS(Posts!$C$2:$C$388,$A8,Posts!$F$2:$F$388,B$5) -> 4 | C8: =COUNTIFS(Posts!$C$2:$C$388,$A8,Posts!$F$2:$F$388,C$5) -> 5 | D8: =COUNTIFS(Posts!$C$2:$C$388,$A8,Posts!$F$2:$F$388,D$5) -> 5 | E8: =COUNTIFS(Posts!$C$2:$C$388,$A8,Posts!$F$2:$F$388,E$5) -> 4 | F8: =COUNTIFS(Posts!$C$2:$C$388,$A8,Posts!$F$2:$F$388,F$5) -> 2 | G8: =COUNTIFS(Posts!$C$2:$C$388,$A8,Posts!$F$2:$F$388,G$5) -> 3 | H8: =COUNTIFS(Posts!$C$2:$C$388,$A8,Posts!$F$2:$F$388,H$5) -> 4 | I8: =COUNTIFS(Posts!$C$2:$C$388,$A8,Posts!$F$2:$F$388,I$5) -> 4 | ... K8: =COUNTIFS(Posts!$C$2:$C$388,$A8,Posts!$F$2:$F$388,K$5) -> 3 | L8: =SUM(B8:K8) -> 38
A9: 2026-04 | B9: =COUNTIFS(Posts!$C$2:$C$388,$A9,Posts!$F$2:$F$388,B$5) -> 6 | C9: =COUNTIFS(Posts!$C$2:$C$388,$A9,Posts!$F$2:$F$388,C$5) -> 6 | D9: =COUNTIFS(Posts!$C$2:$C$388,$A9,Posts!$F$2:$F$388,D$5) -> 4 | E9: =COUNTIFS(Posts!$C$2:$C$388,$A9,Posts!$F$2:$F$388,E$5) -> 4 | F9: =COUNTIFS(Posts!$C$2:$C$388,$A9,Posts!$F$2:$F$388,F$5) -> 2 | G9: =COUNTIFS(Posts!$C$2:$C$388,$A9,Posts!$F$2:$F$388,G$5) -> 3 | H9: =COUNTIFS(Posts!$C$2:$C$388,$A9,Posts!$F$2:$F$388,H$5) -> 4 | I9: =COUNTIFS(Posts!$C$2:$C$388,$A9,Posts!$F$2:$F$388,I$5) -> 4 | ... K9: =COUNTIFS(Posts!$C$2:$C$388,$A9,Posts!$F$2:$F$388,K$5) -> 3 | L9: =SUM(B9:K9) -> 40
A10: 2026-05 | B10: =COUNTIFS(Posts!$C$2:$C$388,$A10,Posts!$F$2:$F$388,B$5) -> 6 | C10: =COUNTIFS(Posts!$C$2:$C$388,$A10,Posts!$F$2:$F$388,C$5) -> 6 | D10: =COUNTIFS(Posts!$C$2:$C$388,$A10,Posts!$F$2:$F$388,D$5) -> 4 | E10: =COUNTIFS(Posts!$C$2:$C$388,$A10,Posts!$F$2:$F$388,E$5) -> 4 | F10: =COUNTIFS(Posts!$C$2:$C$388,$A10,Posts!$F$2:$F$388,F$5) -> 3 | G10: =COUNTIFS(Posts!$C$2:$C$388,$A10,Posts!$F$2:$F$388,G$5) -> 4 | H10: =COUNTIFS(Posts!$C$2:$C$388,$A10,Posts!$F$2:$F$388,H$5) -> 4 | I10: =COUNTIFS(Posts!$C$2:$C$388,$A10,Posts!$F$2:$F$388,I$5) -> 4 | ... K10: =COUNTIFS(Posts!$C$2:$C$388,$A10,Posts!$F$2:$F$388,K$5) -> 4 | L10: =SUM(B10:K10) -> 44
A11: 2026-06 | B11: =COUNTIFS(Posts!$C$2:$C$388,$A11,Posts!$F$2:$F$388,B$5) -> 8 | C11: =COUNTIFS(Posts!$C$2:$C$388,$A11,Posts!$F$2:$F$388,C$5) -> 5 | D11: =COUNTIFS(Posts!$C$2:$C$388,$A11,Posts!$F$2:$F$388,D$5) -> 4 | E11: =COUNTIFS(Posts!$C$2:$C$388,$A11,Posts!$F$2:$F$388,E$5) -> 4 | F11: =COUNTIFS(Posts!$C$2:$C$388,$A11,Posts!$F$2:$F$388,F$5) -> 4 | G11: =COUNTIFS(Posts!$C$2:$C$388,$A11,Posts!$F$2:$F$388,G$5) -> 4 | H11: =COUNTIFS(Posts!$C$2:$C$388,$A11,Posts!$F$2:$F$388,H$5) -> 3 | I11: =COUNTIFS(Posts!$C$2:$C$388,$A11,Posts!$F$2:$F$388,I$5) -> 5 | ... K11: =COUNTIFS(Posts!$C$2:$C$388,$A11,Posts!$F$2:$F$388,K$5) -> 4 | L11: =SUM(B11:K11) -> 46
A12: 2026-07 | B12: =COUNTIFS(Posts!$C$2:$C$388,$A12,Posts!$F$2:$F$388,B$5) -> 8 | C12: =COUNTIFS(Posts!$C$2:$C$388,$A12,Posts!$F$2:$F$388,C$5) -> 6 | D12: =COUNTIFS(Posts!$C$2:$C$388,$A12,Posts!$F$2:$F$388,D$5) -> 4 | E12: =COUNTIFS(Posts!$C$2:$C$388,$A12,Posts!$F$2:$F$388,E$5) -> 4 | F12: =COUNTIFS(Posts!$C$2:$C$388,$A12,Posts!$F$2:$F$388,F$5) -> 4 | G12: =COUNTIFS(Posts!$C$2:$C$388,$A12,Posts!$F$2:$F$388,G$5) -> 6 | H12: =COUNTIFS(Posts!$C$2:$C$388,$A12,Posts!$F$2:$F$388,H$5) -> 3 | I12: =COUNTIFS(Posts!$C$2:$C$388,$A12,Posts!$F$2:$F$388,I$5) -> 5 | ... K12: =COUNTIFS(Posts!$C$2:$C$388,$A12,Posts!$F$2:$F$388,K$5) -> 4 | L12: =SUM(B12:K12) -> 50
A13: 2026-08 | B13: =COUNTIFS(Posts!$C$2:$C$388,$A13,Posts!$F$2:$F$388,B$5) -> 9 | C13: =COUNTIFS(Posts!$C$2:$C$388,$A13,Posts!$F$2:$F$388,C$5) -> 6 | D13: =COUNTIFS(Posts!$C$2:$C$388,$A13,Posts!$F$2:$F$388,D$5) -> 4 | E13: =COUNTIFS(Posts!$C$2:$C$388,$A13,Posts!$F$2:$F$388,E$5) -> 4 | F13: =COUNTIFS(Posts!$C$2:$C$388,$A13,Posts!$F$2:$F$388,F$5) -> 4 | G13: =COUNTIFS(Posts!$C$2:$C$388,$A13,Posts!$F$2:$F$388,G$5) -> 4 | H13: =COUNTIFS(Posts!$C$2:$C$388,$A13,Posts!$F$2:$F$388,H$5) -> 3 | I13: =COUNTIFS(Posts!$C$2:$C$388,$A13,Posts!$F$2:$F$388,I$5) -> 6 | ... K13: =COUNTIFS(Posts!$C$2:$C$388,$A13,Posts!$F$2:$F$388,K$5) -> 4 | L13: =SUM(B13:K13) -> 50
A14: 2026-09 | B14: =COUNTIFS(Posts!$C$2:$C$388,$A14,Posts!$F$2:$F$388,B$5) -> 10 | C14: =COUNTIFS(Posts!$C$2:$C$388,$A14,Posts!$F$2:$F$388,C$5) -> 6 | D14: =COUNTIFS(Posts!$C$2:$C$388,$A14,Posts!$F$2:$F$388,D$5) -> 3 | E14: =COUNTIFS(Posts!$C$2:$C$388,$A14,Posts!$F$2:$F$388,E$5) -> 4 | F14: =COUNTIFS(Posts!$C$2:$C$388,$A14,Posts!$F$2:$F$388,F$5) -> 4 | G14: =COUNTIFS(Posts!$C$2:$C$388,$A14,Posts!$F$2:$F$388,G$5) -> 4 | H14: =COUNTIFS(Posts!$C$2:$C$388,$A14,Posts!$F$2:$F$388,H$5) -> 3 | I14: =COUNTIFS(Posts!$C$2:$C$388,$A14,Posts!$F$2:$F$388,I$5) -> 6 | ... K14: =COUNTIFS(Posts!$C$2:$C$388,$A14,Posts!$F$2:$F$388,K$5) -> 4 | L14: =SUM(B14:K14) -> 50
A15: Jan–Sep | B15: =SUM(B6:B14) -> 58 | C15: =SUM(C6:C14) -> 48 | D15: =SUM(D6:D14) -> 40 | E15: =SUM(E6:E14) -> 36 | F15: =SUM(F6:F14) -> 27 | G15: =SUM(G6:G14) -> 32 | H15: =SUM(H6:H14) -> 32 | I15: =SUM(I6:I14) -> 41 | ... L15: =SUM(L6:L14) -> 387
A17: The Summary sheet calculates its percentages from these counts. Illustrative, synthetic data.

Sheet Posts
A1: post_id | B1: date | C1: month | D1: platform | E1: author | F1: theme | G1: sentiment | H1: likes | I1: reposts | J1: replies | K1: text
A2: P0001 | B2: 46023 | C2: 2026-01 | D2: Bluesky | E2: @researcher_353 | F2: Prices & tokens | G2: positive | H2: 512 | I2: 36 | J2: 84 | K2: Per-token prices dropped again. Our bill went up anyway because we use ten times more.
A3: P0002 | B3: 46025 | C3: 2026-01 | D3: LinkedIn | E3: @researcher_872 | F3: Benchmarks & evals | G3: positive | H3: 12 | I3: 3 | J3: 1 | K3: Started publishing our eval prompts with results. Much better conversations since.
A4: P0003 | B4: 46026 | C4: 2026-01 | D4: Mastodon | E4: @researcher_715 | F4: Agentic coding | G4: neutral | H4: 77 | I4: 5 | J4: 5 | K4: Hot take: the real product is the test suite, the agent just fills it in.
A5: P0004 | B5: 46026 | C5: 2026-01 | D5: LinkedIn | E5: @researcher_761 | F5: Compute & energy | G5: negative | H5: 144 | I5: 41 | J5: 25 | K5: GPU waitlists are shorter this year, power contracts are the new bottleneck.
A6: P0005 | B6: 46026 | C6: 2026-01 | D6: Threads | E6: @researcher_421 | F6: Multimodal & voice | G6: positive | H6: 19 | I6: 4 | J6: 0 | K6: Generated video got good enough that we now watermark all our own footage.
A7: P0006 | B7: 46029 | C7: 2026-01 | D7: Hacker News | E7: @researcher_264 | F7: Benchmarks & evals | G7: neutral | H7: 84 | I7: 15 | J7: 16 | K7: Started publishing our eval prompts with results. Much better conversations since.
A8: P0007 | B8: 46029 | C8: 2026-01 | D8: LinkedIn | E8: @researcher_546 | F8: Multimodal & voice | G8: positive | H8: 27 | I8: 2 | J8: 2 | K8: Voice mode is how my parents use AI now. No typing at all.
A9: P0008 | B9: 46030 | C9: 2026-01 | D9: Bluesky | E9: @researcher_315 | F9: Agentic coding | G9: neutral | H9: 41 | I9: 9 | J9: 5 | K9: Our team now opens more PRs from agents than from humans. Review is the new bottleneck.
A10: P0009 | B10: 46031 | C10: 2026-01 | D10: Mastodon | E10: @researcher_568 | F10: Open-weight models | G10: negative | H10: 22 | I10: 4 | J10: 1 | K10: Another open-weight release that runs on a single workstation GPU. The gap to closed models keeps shrinking.
A11: P0010 | B11: 46031 | C11: 2026-01 | D11: Hacker News | E11: @researcher_593 | F11: Benchmarks & evals | G11: neutral | H11: 151 | I11: 25 | J11: 12 | K11: Benchmark scores up, our internal task success flat. Classic.
A12: P0011 | B12: 46032 | C12: 2026-01 | D12: Bluesky | E12: @researcher_619 | F12: On-device AI | G12: neutral | H12: 33 | I12: 8 | J12: 4 | K12: On-device models finally good enough for note summaries. Privacy team is happy.
A13: P0012 | B13: 46033 | C13: 2026-01 | D13: Hacker News | E13: @researcher_320 | F13: Safety & trust | G13: negative | H13: 132 | I13: 37 | J13: 11 | K13: Users trust answers more when the model shows its sources. Obvious, but measurable.
... A388: P0387 | B388: 46293 | C388: 2026-09 | D388: Reddit | E388: @researcher_143 | F388: Reasoning & test-time compute | G388: positive | H388: 19 | I388: 4 | J388: 1 | K388: Watched a model argue with itself for 40 seconds and get the right answer. Still not sure how I feel.
